<?xml version="1.0" encoding="utf-8"?>
<!-- This URDF was automatically created by SolidWorks to URDF Exporter! Originally created by Stephen Brawner (brawner@gmail.com) 
     Commit Version: 1.5.1-0-g916b5db  Build Version: 1.5.7152.31018
     For more information, please see http://wiki.ros.org/sw_urdf_exporter -->
<robot
  name="051411">
  <link
    name="Body">
    <inertial>
      <origin
        xyz="0.108885138044438 0.0585567936495662 -0.142308649679038"
        rpy="0 0 0" />
      <mass
        value="5.32485366509137" />
      <inertia
        ixx="0.0219378727233069"
        ixy="-4.01751561825009E-06"
        ixz="-1.47975198134055E-06"
        iyy="0.023203020823872"
        iyz="-7.80337093935826E-06"
        izz="0.0149047739346839" />
    </inertial>
    <visual>
      <origin
        xyz="0 0 0"
        rpy="0 0 0" />
      <geometry>
        <mesh
          filename="package://051411/meshes/Body.STL" />
      </geometry>
      <material
        name="">
        <color
          rgba="0.752941176470588 0.752941176470588 0.752941176470588 1" />
      </material>
    </visual>
    <collision>
      <origin
        xyz="0 0 0"
        rpy="0 0 0" />
      <geometry>
        <mesh
          filename="package://051411/meshes/Body.STL" />
      </geometry>
    </collision>
  </link>
  <link
    name="LFS">
    <inertial>
      <origin
        xyz="0.0666875210853818 -0.0256174029954353 0.0272583251967585"
        rpy="0 0 0" />
      <mass
        value="0.26437001106024" />
      <inertia
        ixx="3.20746276473133E-05"
        ixy="-1.44118283521332E-07"
        ixz="-6.30853084344598E-08"
        iyy="6.22704126338855E-05"
        iyz="-2.01894652764198E-07"
        izz="6.28519936954E-05" />
    </inertial>
    <visual>
      <origin
        xyz="0 0 0"
        rpy="0 0 0" />
      <geometry>
        <mesh
          filename="package://051411/meshes/LFS.STL" />
      </geometry>
      <material
        name="">
        <color
          rgba="0.752941176470588 0.752941176470588 0.752941176470588 1" />
      </material>
    </visual>
    <collision>
      <origin
        xyz="0 0 0"
        rpy="0 0 0" />
      <geometry>
        <mesh
          filename="package://051411/meshes/LFS.STL" />
      </geometry>
    </collision>
  </link>
  <joint
    name="LFS"
    type="prismatic">
    <origin
      xyz="0.31516 0.050812 0.026427"
      rpy="2.834 0 3.1416" />
    <parent
      link="Body" />
    <child
      link="LFS" />
    <axis
      xyz="0 0.3028 -0.95305" />
    <limit
      lower="0"
      upper="0"
      effort="0"
      velocity="0" />
  </joint>
  <link
    name="LFW">
    <inertial>
      <origin
        xyz="-0.012315724574073 0 3.46944695195361E-18"
        rpy="0 0 0" />
      <mass
        value="0.193585420779862" />
      <inertia
        ixx="0.000253081141332254"
        ixy="-2.20697783538624E-23"
        ixz="8.87721135180224E-22"
        iyy="0.000136818598566517"
        iyz="0"
        izz="0.000136818598566517" />
    </inertial>
    <visual>
      <origin
        xyz="0 0 0"
        rpy="0 0 0" />
      <geometry>
        <mesh
          filename="package://051411/meshes/LFW.STL" />
      </geometry>
      <material
        name="">
        <color
          rgba="1 1 1 1" />
      </material>
    </visual>
    <collision>
      <origin
        xyz="0 0 0"
        rpy="0 0 0" />
      <geometry>
        <mesh
          filename="package://051411/meshes/LFW.STL" />
      </geometry>
    </collision>
  </link>
  <joint
    name="LFW"
    type="continuous">
    <origin
      xyz="0.00041099 -0.047479 0.052309"
      rpy="-1.8707 0 3.1416" />
    <parent
      link="LFS" />
    <child
      link="LFW" />
    <axis
      xyz="1 0 0" />
    <limit
      effort="3.1"
      velocity="7" />
  </joint>
  <link
    name="RFS">
    <inertial>
      <origin
        xyz="0.0724473276378503 -0.0316832521314762 0.0253402400459297"
        rpy="0 0 0" />
      <mass
        value="0.26437001106024" />
      <inertia
        ixx="3.20746276473134E-05"
        ixy="1.44118283521343E-07"
        ixz="6.30853084344513E-08"
        iyy="6.22704126338856E-05"
        iyz="-2.018946527642E-07"
        izz="6.28519936954001E-05" />
    </inertial>
    <visual>
      <origin
        xyz="0 0 0"
        rpy="0 0 0" />
      <geometry>
        <mesh
          filename="package://051411/meshes/RFS.STL" />
      </geometry>
      <material
        name="">
        <color
          rgba="0.752941176470588 0.752941176470588 0.752941176470588 1" />
      </material>
    </visual>
    <collision>
      <origin
        xyz="0 0 0"
        rpy="0 0 0" />
      <geometry>
        <mesh
          filename="package://051411/meshes/RFS.STL" />
      </geometry>
    </collision>
  </link>
  <joint
    name="RFS"
    type="prismatic">
    <origin
      xyz="-0.10492 0.012128 0.026427"
      rpy="2.834 0 0" />
    <parent
      link="Body" />
    <child
      link="RFS" />
    <axis
      xyz="0 0.3028 -0.95305" />
    <limit
      lower="0"
      upper="0"
      effort="0"
      velocity="0" />
  </joint>
  <link
    name="RFW">
    <inertial>
      <origin
        xyz="-0.012315724574073 -3.46944695195361E-18 6.93889390390723E-18"
        rpy="0 0 0" />
      <mass
        value="0.193585420779862" />
      <inertia
        ixx="0.000253081141332253"
        ixy="1.52152873461367E-21"
        ixz="2.90805277918717E-21"
        iyy="0.000136818598566517"
        iyz="-1.6940658945086E-20"
        izz="0.000136818598566517" />
    </inertial>
    <visual>
      <origin
        xyz="0 0 0"
        rpy="0 0 0" />
      <geometry>
        <mesh
          filename="package://051411/meshes/RFW.STL" />
      </geometry>
      <material
        name="">
        <color
          rgba="1 1 1 1" />
      </material>
    </visual>
    <collision>
      <origin
        xyz="0 0 0"
        rpy="0 0 0" />
      <geometry>
        <mesh
          filename="package://051411/meshes/RFW.STL" />
      </geometry>
    </collision>
  </link>
  <joint
    name="RFW"
    type="continuous">
    <origin
      xyz="0.0061708 -0.028286 0.058405"
      rpy="-0.70714 0 3.1416" />
    <parent
      link="RFS" />
    <child
      link="RFW" />
    <axis
      xyz="1 0 0" />
    <limit
      effort="3.1"
      velocity="7" />
  </joint>
  <link
    name="LBS">
    <inertial>
      <origin
        xyz="0.0754022136877308 -0.0206011352566475 0.0126264314730576"
        rpy="0 0 0" />
      <mass
        value="0.197009126147877" />
      <inertia
        ixx="1.68802738687172E-05"
        ixy="-4.80660454962433E-21"
        ixz="2.20351163892655E-20"
        iyy="5.02184885667569E-05"
        iyz="1.0508875929185E-06"
        izz="4.72447473350486E-05" />
    </inertial>
    <visual>
      <origin
        xyz="0 0 0"
        rpy="0 0 0" />
      <geometry>
        <mesh
          filename="package://051411/meshes/LBS.STL" />
      </geometry>
      <material
        name="">
        <color
          rgba="0.752941176470588 0.752941176470588 0.752941176470588 1" />
      </material>
    </visual>
    <collision>
      <origin
        xyz="0 0 0"
        rpy="0 0 0" />
      <geometry>
        <mesh
          filename="package://051411/meshes/LBS.STL" />
      </geometry>
    </collision>
  </link>
  <joint
    name="LBS"
    type="prismatic">
    <origin
      xyz="0.31516 0.23081 0.01777"
      rpy="2.834 0 3.1416" />
    <parent
      link="Body" />
    <child
      link="LBS" />
    <axis
      xyz="0 0.3028 -0.95305" />
    <limit
      lower="0"
      upper="0"
      effort="0"
      velocity="0" />
  </joint>
  <link
    name="LBC">
    <inertial>
      <origin
        xyz="0.000464526735875048 -0.0408313152633741 -2.77555756156289E-17"
        rpy="0 0 0" />
      <mass
        value="0.0433962459602619" />
      <inertia
        ixx="2.1180042472488E-05"
        ixy="5.53822046363832E-07"
        ixz="-7.94093388050907E-23"
        iyy="1.76453344713605E-06"
        iyz="-5.89821135780936E-21"
        izz="2.14947085785555E-05" />
    </inertial>
    <visual>
      <origin
        xyz="0 0 0"
        rpy="0 0 0" />
      <geometry>
        <mesh
          filename="package://051411/meshes/LBC.STL" />
      </geometry>
      <material
        name="">
        <color
          rgba="0.898039215686275 0.917647058823529 0.929411764705882 1" />
      </material>
    </visual>
    <collision>
      <origin
        xyz="0 0 0"
        rpy="0 0 0" />
      <geometry>
        <mesh
          filename="package://051411/meshes/LBC.STL" />
      </geometry>
    </collision>
  </link>
  <joint
    name="LBC"
    type="continuous">
    <origin
      xyz="0.041161 -0.016816 0.00071326"
      rpy="-1.8784 -0.0013926 3.1372" />
    <parent
      link="LBS" />
    <child
      link="LBC" />
    <axis
      xyz="0 1 0" />
  </joint>
  <link
    name="LBW">
    <inertial>
      <origin
        xyz="0.00647305835345524 0 0"
        rpy="0 0 0" />
      <mass
        value="0.0368891747697499" />
      <inertia
        ixx="1.67269024516251E-05"
        ixy="-6.05909798695093E-22"
        ixz="6.3097337125545E-21"
        iyy="8.87926239042531E-06"
        iyz="-3.17637355220363E-22"
        izz="8.87926239042531E-06" />
    </inertial>
    <visual>
      <origin
        xyz="0 0 0"
        rpy="0 0 0" />
      <geometry>
        <mesh
          filename="package://051411/meshes/LBW.STL" />
      </geometry>
      <material
        name="">
        <color
          rgba="1 1 1 1" />
      </material>
    </visual>
    <collision>
      <origin
        xyz="0 0 0"
        rpy="0 0 0" />
      <geometry>
        <mesh
          filename="package://051411/meshes/LBW.STL" />
      </geometry>
    </collision>
  </link>
  <joint
    name="LBW"
    type="continuous">
    <origin
      xyz="0.0095003 -0.068304 0"
      rpy="-2.9662 0 0" />
    <parent
      link="LBC" />
    <child
      link="LBW" />
    <axis
      xyz="1 0 0" />
    <limit
      effort="3.1"
      velocity="7" />
  </joint>
  <link
    name="RBS">
    <inertial>
      <origin
        xyz="0.0754022136877307 -0.0206011352566388 0.0126264314730556"
        rpy="0 0 0" />
      <mass
        value="0.197009126147877" />
      <inertia
        ixx="1.68802738687172E-05"
        ixy="1.02895547362818E-20"
        ixz="-2.43496363718604E-20"
        iyy="5.0218488566757E-05"
        iyz="1.0508875929185E-06"
        izz="4.72447473350487E-05" />
    </inertial>
    <visual>
      <origin
        xyz="0 0 0"
        rpy="0 0 0" />
      <geometry>
        <mesh
          filename="package://051411/meshes/RBS.STL" />
      </geometry>
      <material
        name="">
        <color
          rgba="0.752941176470588 0.752941176470588 0.752941176470588 1" />
      </material>
    </visual>
    <collision>
      <origin
        xyz="0 0 0"
        rpy="0 0 0" />
      <geometry>
        <mesh
          filename="package://051411/meshes/RBS.STL" />
      </geometry>
    </collision>
  </link>
  <joint
    name="RBS"
    type="prismatic">
    <origin
      xyz="-0.099161 0.19919 0.01777"
      rpy="2.834 0 0" />
    <parent
      link="Body" />
    <child
      link="RBS" />
    <axis
      xyz="0 0.3028 -0.95305" />
    <limit
      lower="0"
      upper="0"
      effort="0"
      velocity="0" />
  </joint>
  <link
    name="RBC">
    <inertial>
      <origin
        xyz="0.000464526735875062 -0.0408313152633741 0"
        rpy="0 0 0" />
      <mass
        value="0.0433962459602619" />
      <inertia
        ixx="2.1180042472488E-05"
        ixy="5.53822046363839E-07"
        ixz="-2.7069360738408E-22"
        iyy="1.76453344713605E-06"
        iyz="-3.31023923512817E-21"
        izz="2.14947085785555E-05" />
    </inertial>
    <visual>
      <origin
        xyz="0 0 0"
        rpy="0 0 0" />
      <geometry>
        <mesh
          filename="package://051411/meshes/RBC.STL" />
      </geometry>
      <material
        name="">
        <color
          rgba="0.898039215686275 0.917647058823529 0.929411764705882 1" />
      </material>
    </visual>
    <collision>
      <origin
        xyz="0 0 0"
        rpy="0 0 0" />
      <geometry>
        <mesh
          filename="package://051411/meshes/RBC.STL" />
      </geometry>
    </collision>
  </link>
  <joint
    name="RBC"
    type="continuous">
    <origin
      xyz="0.041161 -0.016816 0.00071326"
      rpy="-1.8784 0 3.1416" />
    <parent
      link="RBS" />
    <child
      link="RBC" />
    <axis
      xyz="0 1 0" />
  </joint>
  <link
    name="RBW">
    <inertial>
      <origin
        xyz="0.00647333333471937 -5.55111512312578E-17 -5.55111512312578E-17"
        rpy="0 0 0" />
      <mass
        value="0.0368891747697499" />
      <inertia
        ixx="1.67269024516251E-05"
        ixy="-2.32726892683381E-21"
        ixz="-4.86067499904064E-21"
        iyy="8.8792623904253E-06"
        iyz="-8.470329472543E-22"
        izz="8.8792623904253E-06" />
    </inertial>
    <visual>
      <origin
        xyz="0 0 0"
        rpy="0 0 0" />
      <geometry>
        <mesh
          filename="package://051411/meshes/RBW.STL" />
      </geometry>
      <material
        name="">
        <color
          rgba="1 1 1 1" />
      </material>
    </visual>
    <collision>
      <origin
        xyz="0 0 0"
        rpy="0 0 0" />
      <geometry>
        <mesh
          filename="package://051411/meshes/RBW.STL" />
      </geometry>
    </collision>
  </link>
  <joint
    name="RBW"
    type="continuous">
    <origin
      xyz="0.0095 -0.068304 0"
      rpy="0.99137 0 0" />
    <parent
      link="RBC" />
    <child
      link="RBW" />
    <axis
      xyz="1 0 0" />
    <limit
      effort="3.1"
      velocity="7" />
  </joint>
  <link
    name="front_cam">
    <inertial>
      <origin
        xyz="0.0498359968949385 0.0617836354959193 0.0687226592240569"
        rpy="0 0 0" />
      <mass
        value="0.0436119950287128" />
      <inertia
        ixx="4.29479133591131E-06"
        ixy="-8.85791114122617E-10"
        ixz="-1.01813691701076E-09"
        iyy="2.21058141232447E-05"
        iyz="2.17579681215275E-08"
        izz="2.35707058046401E-05" />
    </inertial>
    <visual>
      <origin
        xyz="0 0 0"
        rpy="0 0 0" />
      <geometry>
        <mesh
          filename="package://051411/meshes/front_cam.STL" />
      </geometry>
      <material
        name="">
        <color
          rgba="0.792156862745098 0.819607843137255 0.933333333333333 1" />
      </material>
    </visual>
    <collision>
      <origin
        xyz="0 0 0"
        rpy="0 0 0" />
      <geometry>
        <mesh
          filename="package://051411/meshes/front_cam.STL" />
      </geometry>
    </collision>
  </link>
  <joint
    name="front_cam"
    type="fixed">
    <origin
      xyz="0.058161 0.080278 0.069504"
      rpy="1.5708 0 0" />
    <parent
      link="Body" />
    <child
      link="front_cam" />
    <axis
      xyz="0 0 0" />
  </joint>
  <link
    name="ball_cam">
    <inertial>
      <origin
        xyz="0.049835996914947 0.0617836350059216 -0.003746181077359"
        rpy="0 0 0" />
      <mass
        value="0.0436119951630769" />
      <inertia
        ixx="4.29479053059235E-06"
        ixy="-8.85260765936133E-10"
        ixz="-1.01843552509082E-09"
        iyy="2.21058148138206E-05"
        iyz="2.17580969417583E-08"
        izz="2.3570705705494E-05" />
    </inertial>
    <visual>
      <origin
        xyz="0 0 0"
        rpy="0 0 0" />
      <geometry>
        <mesh
          filename="package://051411/meshes/ball_cam.STL" />
      </geometry>
      <material
        name="">
        <color
          rgba="0.792156862745098 0.819607843137255 0.933333333333333 1" />
      </material>
    </visual>
    <collision>
      <origin
        xyz="0 0 0"
        rpy="0 0 0" />
      <geometry>
        <mesh
          filename="package://051411/meshes/ball_cam.STL" />
      </geometry>
    </collision>
  </link>
  <joint
    name="ball_cam"
    type="fixed">
    <origin
      xyz="0.058165 0.048961 0.044286"
      rpy="2.2021 0 0" />
    <parent
      link="Body" />
    <child
      link="ball_cam" />
    <axis
      xyz="0 0 1" />
  </joint>
  <link
    name="Lidar">
    <inertial>
      <origin
        xyz="-0.0784930224009142 -0.74442743376688 -0.133449662212527"
        rpy="0 0 0" />
      <mass
        value="0.0730845703902162" />
      <inertia
        ixx="1.95808756635695E-05"
        ixy="4.28391179298426E-07"
        ixz="-1.03933565415068E-07"
        iyy="4.14184515330581E-05"
        iyz="-9.42709167560436E-09"
        izz="2.41250078994433E-05" />
    </inertial>
    <visual>
      <origin
        xyz="0 0 0"
        rpy="0 0 0" />
      <geometry>
        <mesh
          filename="package://051411/meshes/Lidar.STL" />
      </geometry>
      <material
        name="">
        <color
          rgba="0.792156862745098 0.819607843137255 0.933333333333333 1" />
      </material>
    </visual>
    <collision>
      <origin
        xyz="0 0 0"
        rpy="0 0 0" />
      <geometry>
        <mesh
          filename="package://051411/meshes/Lidar.STL" />
      </geometry>
    </collision>
  </link>
  <joint
    name="Lidar"
    type="fixed">
    <origin
      xyz="0.24092 0.098561 -0.57169"
      rpy="-1.5708 0 -1.5708" />
    <parent
      link="Body" />
    <child
      link="Lidar" />
    <axis
      xyz="0 0 0" />
  </joint>
</robot>